Traceback (most recent call last):
  File "/home/bleyerj/.local/lib/python3.10/site-packages/jupyter_cache/executors/utils.py", line 58, in single_nb_execution
    executenb(
  File "/home/bleyerj/.local/lib/python3.10/site-packages/nbclient/client.py", line 1305, in execute
    return NotebookClient(nb=nb, resources=resources, km=km, **kwargs).execute()
  File "/home/bleyerj/.local/lib/python3.10/site-packages/jupyter_core/utils/__init__.py", line 166, in wrapped
    return loop.run_until_complete(inner)
  File "/usr/lib/python3.10/asyncio/base_events.py", line 649, in run_until_complete
    return future.result()
  File "/home/bleyerj/.local/lib/python3.10/site-packages/nbclient/client.py", line 705, in async_execute
    await self.async_execute_cell(
  File "/home/bleyerj/.local/lib/python3.10/site-packages/nbclient/client.py", line 1058, in async_execute_cell
    await self._check_raise_for_error(cell, cell_index, exec_reply)
  File "/home/bleyerj/.local/lib/python3.10/site-packages/nbclient/client.py", line 914, in _check_raise_for_error
    raise CellExecutionError.from_cell_and_msg(cell, exec_reply_content)
nbclient.exceptions.CellExecutionError: An error occurred while executing the following cell:
------------------
F0 = fem.Constant(domain, np.zeros((gdim,)))
L_form = fem.form(ufl.dot(F0, u_) * dx)

A = fem.petsc.assemble_matrix(a_form, bcs=bcs)
A.assemble()
b = fem.petsc.create_vector(L_form)

b.array[:] = F
------------------

----- stderr -----
WARNING:py.warnings:/usr/lib/python3/dist-packages/ufl/core/terminal.py:60: UserWarning: Couldn't map 'f' to a float, returning ufl object without evaluation.
  warnings.warn(f"Couldn't map '{self}' to a float, returning ufl object without evaluation.")
------------------

[0;31m---------------------------------------------------------------------------[0m
[0;31mTypeError[0m                                 Traceback (most recent call last)
[0;31mTypeError[0m: Indexed.__float__ returned non-float (type NotImplementedType)

The above exception was the direct cause of the following exception:

[0;31mValueError[0m                                Traceback (most recent call last)
Cell [0;32mIn[8], line 8[0m
[1;32m      5[0m A[38;5;241m.[39massemble()
[1;32m      6[0m b [38;5;241m=[39m fem[38;5;241m.[39mpetsc[38;5;241m.[39mcreate_vector(L_form)
[0;32m----> 8[0m [43mb[49m[38;5;241;43m.[39;49m[43marray[49m[43m[[49m[43m:[49m[43m][49m [38;5;241m=[39m F

[0;31mValueError[0m: setting an array element with a sequence.

