Traceback (most recent call last):
  File "/home/bleyerj/.local/lib/python3.12/site-packages/jupyter_cache/executors/utils.py", line 58, in single_nb_execution
    executenb(
  File "/home/bleyerj/.local/lib/python3.12/site-packages/nbclient/client.py", line 1314, in execute
    return NotebookClient(nb=nb, resources=resources, km=km, **kwargs).execute()
           ^^^^^^^^^^^^^^^^^^^^^^^^^^^^^^^^^^^^^^^^^^^^^^^^^^^^^^^^^^^^^^^^^^^^^
  File "/home/bleyerj/.local/lib/python3.12/site-packages/jupyter_core/utils/__init__.py", line 165, in wrapped
    return loop.run_until_complete(inner)
           ^^^^^^^^^^^^^^^^^^^^^^^^^^^^^^
  File "/usr/lib/python3.12/asyncio/base_events.py", line 687, in run_until_complete
    return future.result()
           ^^^^^^^^^^^^^^^
  File "/home/bleyerj/.local/lib/python3.12/site-packages/nbclient/client.py", line 709, in async_execute
    await self.async_execute_cell(
  File "/home/bleyerj/.local/lib/python3.12/site-packages/nbclient/client.py", line 1062, in async_execute_cell
    await self._check_raise_for_error(cell, cell_index, exec_reply)
  File "/home/bleyerj/.local/lib/python3.12/site-packages/nbclient/client.py", line 918, in _check_raise_for_error
    raise CellExecutionError.from_cell_and_msg(cell, exec_reply_content)
nbclient.exceptions.CellExecutionError: An error occurred while executing the following cell:
------------------
import numpy as np
from pathlib import Path
import pyvista
from mpi4py import MPI
import ufl
from dolfinx import mesh, fem, io, plot
import dolfinx.fem.petsc

domain, markers, facets = io.gmshio.read_from_msh("I_beam.msh", MPI.COMM_WORLD)

gdim = domain.geometry.dim
tdim = domain.topology.dim

print(f"Geometrical dimension = {gdim}")
print(f"Topological dimension = {tdim}")

pyvista.set_jupyter_backend("static")
plotter = pyvista.Plotter()
ugrid = pyvista.UnstructuredGrid(*plot.vtk_mesh(domain))
plotter.add_mesh(ugrid, show_edges=True)
plotter.show_axes()
plotter.show()
------------------


[0;31m---------------------------------------------------------------------------[0m
[0;31mModuleNotFoundError[0m                       Traceback (most recent call last)
Cell [0;32mIn[1], line 3[0m
[1;32m      1[0m [38;5;28;01mimport[39;00m [38;5;21;01mnumpy[39;00m [38;5;28;01mas[39;00m [38;5;21;01mnp[39;00m
[1;32m      2[0m [38;5;28;01mfrom[39;00m [38;5;21;01mpathlib[39;00m [38;5;28;01mimport[39;00m Path
[0;32m----> 3[0m [38;5;28;01mimport[39;00m [38;5;21;01mpyvista[39;00m
[1;32m      4[0m [38;5;28;01mfrom[39;00m [38;5;21;01mmpi4py[39;00m [38;5;28;01mimport[39;00m MPI
[1;32m      5[0m [38;5;28;01mimport[39;00m [38;5;21;01mufl[39;00m

[0;31mModuleNotFoundError[0m: No module named 'pyvista'

