Traceback (most recent call last):
  File "/home/bleyerj/.local/lib/python3.10/site-packages/jupyter_cache/executors/utils.py", line 58, in single_nb_execution
    executenb(
  File "/home/bleyerj/.local/lib/python3.10/site-packages/nbclient/client.py", line 1305, in execute
    return NotebookClient(nb=nb, resources=resources, km=km, **kwargs).execute()
  File "/home/bleyerj/.local/lib/python3.10/site-packages/jupyter_core/utils/__init__.py", line 166, in wrapped
    return loop.run_until_complete(inner)
  File "/usr/lib/python3.10/asyncio/base_events.py", line 649, in run_until_complete
    return future.result()
  File "/home/bleyerj/.local/lib/python3.10/site-packages/nbclient/client.py", line 705, in async_execute
    await self.async_execute_cell(
  File "/home/bleyerj/.local/lib/python3.10/site-packages/nbclient/client.py", line 1058, in async_execute_cell
    await self._check_raise_for_error(cell, cell_index, exec_reply)
  File "/home/bleyerj/.local/lib/python3.10/site-packages/nbclient/client.py", line 914, in _check_raise_for_error
    raise CellExecutionError.from_cell_and_msg(cell, exec_reply_content)
nbclient.exceptions.CellExecutionError: An error occurred while executing the following cell:
------------------
import pyvista
from dolfinx import plot

pyvista.set_jupyter_backend("static")

topology, cell_types, geometry = plot.vtk_mesh(domain, 2)
grid = pyvista.UnstructuredGrid(topology, cell_types, geometry)
grid.cell_data["k"] = k.x.array
grid.set_active_scalar("k")
# Create plotter and pyvista grid
p = pyvista.Plotter()
p.add_mesh(grid, show_edges=True)
p.view_xy()
p.show_axes()
p.show()
------------------


[0;31m---------------------------------------------------------------------------[0m
[0;31mAttributeError[0m                            Traceback (most recent call last)
Cell [0;32mIn[5], line 9[0m
[1;32m      7[0m grid [38;5;241m=[39m pyvista[38;5;241m.[39mUnstructuredGrid(topology, cell_types, geometry)
[1;32m      8[0m grid[38;5;241m.[39mcell_data[[38;5;124m"[39m[38;5;124mk[39m[38;5;124m"[39m] [38;5;241m=[39m k[38;5;241m.[39mx[38;5;241m.[39marray
[0;32m----> 9[0m [43mgrid[49m[38;5;241;43m.[39;49m[43mset_active_scalar[49m([38;5;124m"[39m[38;5;124mk[39m[38;5;124m"[39m)
[1;32m     10[0m [38;5;66;03m# Create plotter and pyvista grid[39;00m
[1;32m     11[0m p [38;5;241m=[39m pyvista[38;5;241m.[39mPlotter()

File [0;32m~/.local/lib/python3.10/site-packages/pyvista/core/dataset.py:150[0m, in [0;36mDataSet.__getattr__[0;34m(self, item)[0m
[1;32m    148[0m [38;5;28;01mdef[39;00m [38;5;21m__getattr__[39m([38;5;28mself[39m, item) [38;5;241m-[39m[38;5;241m>[39m Any:
[1;32m    149[0m [38;5;250m    [39m[38;5;124;03m"""Get attribute from base class if not found."""[39;00m
[0;32m--> 150[0m     [38;5;28;01mreturn[39;00m [38;5;28;43msuper[39;49m[43m([49m[43m)[49m[38;5;241;43m.[39;49m[38;5;21;43m__getattribute__[39;49m[43m([49m[43mitem[49m[43m)[49m

[0;31mAttributeError[0m: 'UnstructuredGrid' object has no attribute 'set_active_scalar'

